Workbook
Name ProvinceD: [1]ProvinceDistrict!$I$2:$I$8
Name ProvinceList: [1]ProvinceDistrict!#REF!

Sheet Poush
B1: Gurans Laghubitta Bittiya Sanstha Ltd.
B2: u'/fF; n3'ljQ ljQLo ;+:yf ln=
A3: Central Office : Hulak Tole, Dhankuta-7, Dhankuta, Corporate Office Budhiganga-1, Morang
A4: Tel:- 021-420453,420323 , Email : guranslbbs@gmail.com, Web: www.guranslaghubitta.com.np
A5: Unaudited Financial Results (Quarterly)
A6: As at 2nd Quarter ended on 30 Poush, 2079 of the F/Y 2079/080
A7: (Rs. in '000')
A8: S.N. | B8: Particulars | C8: This Quarter Ending | D8: Previous Quarter Ending | E8: Corresponding Previous Year Quarter Ending
A9: 1 | B9: Total Capital & Liabilities (1.1 to 1.7) | C9: =C10+C11+C13+C14+C17+C18 -> 1361683.1 | D9: =D10+D11+D13+D14+D17+D18 -> 1383241.4 | E9: =E10+E11+E13+E14+E17+E18 -> 1319638
A10: 1.1 | B10: Paid-up Capital | C10: =97500+3900 -> 101400 | D10: 97500 | E10: 97500
A11: 1.2 | B11: Reserves and Surplus | C11: =24449.07-3900 -> 20549.07 | D11: 26742.21 | E11: 27630.63 | G11: ='[2]9.5'!$D$9 -> 30741.859
A12: 1.3 | B12: Debenture and Bond | D12: - | E12: -
A13: 1.4 | B13: Borrowings | C13: 802435.25 | D13: 827725.95 | E13: 841025.05
A14: 1.5 | B14: Deposits (a+b) | C14: =C15 -> 323901.22 | D14: =D15 -> 311058.31 | E14: =E15 -> 246448.95 | F14: =C14-E14 -> 77452.27
B15: a. Domestic Currency | C15: 323901.22 | D15: 311058.31 | E15: 246448.95
B16: b. Foreign Currency | C16: - | D16: - | E16: -
A17: 1.6 | B17: Income Tax Liabilities | C17: 106.27 | D17: 5315.05 | E17: 3166.8 | F17: =C17-E17 -> -3060.53
A18: 1.7 | B18: Other Liabilities | C18: 113291.29 | D18: 114899.91 | E18: 103866.55 | F18: =C18-E18 -> 9424.74
A19: 2 | B19: Total Assets (2.1 to 2.7) | C19: =C20+C21+C23+C24+C26+C22 -> 1361683.1 | D19: =D20+D21+D23+D24+D26+D22 -> 1383241.4 | E19: =E20+E21+E23+E24+E26+E22 -> 1319638 | F19: =D19-D9 -> 0 | G19: =E19-E9 -> 0 | H19: =C19-C9 -> 0
A20: 2.1 | B20: Cash & Bank Balance | C20: 12733.22 | D20: 16960.96 | E20: 13013.26
A21: 2.2 | B21: Money at call and short Notice | C21: 46219.99 | D21: 31609.09 | E21: 20813.2
A22: 2.3 | B22: Investments | C22: 10000 | D22: 10000 | E22: 10000
A23: 2.4 | B23: Loans & Advances (a+b+c+d+e+f) | C23: 1216157.7 | D23: 1245695.7 | E23: 1179188.1 | F23: =C23-E23 -> 36969.61 | G23: =F23/E23*100 -> 3.1351749
A24: 2.5 | B24: Fixed Assets | C24: 21251.44 | D24: 20805.14 | E24: 19460.94 | F24: =C24-E24 -> 1790.5
A25: 2.6 | B25: Non Banking Assets | C25: 0 | D25: 0 | E25: 0 | F25: =C25-E25 -> 0
A26: 2.7 | B26: Other Assets | C26: 55320.71 | D26: 58170.56 | E26: 77162.45 | F26: =C26-E26 -> -21841.74
A27: 3 | B27: Profit and Loss Account | C27: - | D27: - | E27: -
A28: 3.1 | B28: Interest income | C28: 82322.48 | D28: 36113.33 | E28: 74211 | F28: =C28-E28 -> 8111.48 | G28: =F28/E28*100 -> 10.930293
A29: 3.2 | B29: Interest Expense | C29: 59869.15 | D29: 30185.81 | E29: 39087.4 | F29: =C29-E29 -> 20781.75 | G29: =F29/E29*100 -> 53.167389
A30: A | B30: Net Interest Income (3.1-3.2) | C30: =C28-C29 -> 22453.33 | D30: =D28-D29 -> 5927.52 | E30: =E28-E29 -> 35123.6
A31: 3.3 | B31: Fees Commission and Discount | C31: 478.91 | D31: 326.45 | E31: 782.1 | F31: =C31-E31 -> -303.19 | G31: =F31/E31*100 -> -38.766142
A32: 3.4 | B32: Other Operating Income | C32: 12380.73 | D32: 6228.09 | E32: 14283.78 | F32: =C32-E32 -> -1903.05 | G32: =F32/E32*100 -> -13.323154
A33: 3.5 | B33: Foreign Exchange Gain/Loss (Net) | C33: - | D33: - | E33: -
A34: B | B34: Total Operating Income (A+3.3+3.4+3.5) | C34: =C30+C32+C31 -> 35312.97 | D34: =D32+D30+D31 -> 12482.06 | E34: =E32+E30+E31 -> 50189.48
A35: 3.6 | B35: Staff Expenses | C35: 26848.8 | D35: 14387.4 | E35: 25735.54 | F35: =C35-E35 -> 1113.26 | G35: =F35/E35*100 -> 4.325769
A36: 3.7 | B36: Other Operating Expenses | C36: 9846.37 | D36: 3481.83 | E36: 9458.45 | F36: =C36-E36 -> 387.92 | G36: =F36/E36*100 -> 4.1013062
A37: C | B37: Operating profit Before Provision (B-3.6-3.7) | C37: =C34-C35-C36 -> -1382.2 | D37: =D34-D35-D36 -> -5387.17 | E37: =E34-E35-E36 -> 14995.49
A38: 3.8 | B38: Provision for Possible Loss | C38: =35667.96-37430.16 -> -1762.2 | D38: =14964.03-14328.64 -> 635.39 | E38: =62471.55-59087.64 -> 3383.91 | F38: =C38-E38 -> -5146.11 | G38: =F38/E38*100 -> -152.07585
A39: D | B39: Operating profit (C-3.8) | C39: =C37-C38 -> 380 | D39: =D37-D38 -> -6022.56 | E39: =E37-E38 -> 11611.58
A40: 3.9 | B40: Non Operating Income/Expenses (Net) | C40: 9.64 | D40: 0 | E40: 0 | I40: 86266.634 | J40: =68870.32 -> 68870.32 | K40: =157989.62 -> 157989.62
...

Sheet Ratio 
A1: calculation sheet
A2: Per share income | C2: =B3/B4 -> 0.48905325
A3: Net income | B3: =(Poush!C47*1000)/6*12 -> 495900 | D3: =Poush!C47 -> 247.95
A4: No Of Share | B4: =Poush!C10*10 -> 1014000
A6: P/E ratio | C6: =B7/B8 -> 1803.4846
A7: Market price per share | B7: 882
A8: EPS | B8: =C2 -> 0.48905325
A10: Net worth | C10: =B13/B14 -> 0.12026536 | D10: =C10*1000 -> 120.26536
A11: Total Assets | B11: =Poush!C19 -> 1361683.1
A12: Total Liability | B12: =Poush!C13+Poush!C14+Poush!C18+Poush!C17 -> 1239734
A13: Net | B13: =B11-B12 -> 121949.07
A14: No share out | B14: =B4 -> 1014000
A16: Per share total assets | C16: =B17/B18*1000 -> 1342.8827 | H16: 82621086
A17: Total Assets | B17: =Poush!C19 -> 1361683.1 | H17: 3.1714234e+08
A18: No of share outstanding | B18: =Poush!C10*10 -> 1014000 | H18: 7928558.5 | I18: =H16+H17-H18 -> 3.9183487e+08
H19: 74692527
A20: Liquidity Ratio/ Quick ratio | C20: =B21/B22 -> 0.16633922 | D20: =C20*100 -> 16.633922
A21: Bank and Cash Balance | B21: =Poush!C20+Poush!C21-6200000/1000 -> 52753.21
A22: Deposit | B22: =H17/1000 -> 317142.34

Sheet Cost of Fund 
A1: Gurans Laghubitta Bitiya Sanstha Ltd
A2: Dhankuta -7, Dhankuta Hulak Tol
A3: Statement of Cost of Fund for the FY 079.80 | H3: Base Rate
A4: Month | C4: Cost of Fund as per NRB
A5: Sharawan | C5: 11.13 | H5: Cost of Fund | I5: =E10 -> 10.638333
A6: Bhadra | C6: 10.79 | H6: Cost of CRR | I6: 0.07
A7: Ashoj | C7: 9.55 | D7: =C5+C6+C7 -> 31.47 | E7: =D7/3 -> 10.49 | H7: Cost of SLR | I7: 0.03
A8: Kartik | C8: 9.67 | H8: Operating Cost | I8: 7.47
A9: Mangsir | C9: 9.69 | H9: Base Rate | I9: =SUM(I5:I8) -> 18.208333
A10: Poush | C10: 13 | D10: =C5+C6+C7+C8+C9+C10 -> 63.83 | E10: =D10/6 -> 10.638333
A11: Magh
A12: Falgun
A13: Chaitra | D13: =SUM(C5:C13) -> 63.83 | E13: =D13/9 -> 7.0922222
A14: Baishak 079
A15: Jestha 079
A16: Ashad 079 | D16: =SUM(C5:C16) -> 63.83 | E16: =D16/12 -> 5.3191667
A17: Total | C17: =SUM(C5:C16) -> 63.83
A18: Month | C18: 12
A19: Average cost of Fund | C19: =C17/C18 -> 5.3191667
